2023-05-27 09:40:30,596 INFO: Tinker Full-stack App [in /mnt/c/Users/Administrator/Desktop/html/Chapter-12/app/__init__.py:48]
2023-05-27 09:40:46,297 INFO: Tinker Full-stack App [in /mnt/c/Users/Administrator/Desktop/html/Chapter-12/app/__init__.py:48]
2023-05-27 09:41:29,785 INFO: Tinker Full-stack App [in /mnt/c/Users/Administrator/Desktop/html/Chapter-12/app/__init__.py:48]
2023-05-27 09:52:56,977 INFO: Tinker Full-stack App [in /mnt/c/Users/Administrator/Desktop/html/Chapter-12/app/__init__.py:48]
2023-05-27 10:59:52,193 INFO: Tinker Full-stack App [in /mnt/c/Users/Administrator/Desktop/html/Chapter-12/app/__init__.py:48]
2023-05-29 21:21:10,572 INFO: Tinker Full-stack App [in /mnt/c/Users/Administrator/Desktop/html/Chapter-12/app/__init__.py:48]
2023-06-01 11:54:22,204 INFO: Tinker Full-stack App [in /mnt/c/Users/Administrator/Desktop/html/Chapter-12/app/__init__.py:48]
2023-06-01 11:54:53,657 ERROR: Exception on /sd/profile [GET] [in /mnt/c/Users/Administrator/Desktop/html/Chapter-12/venv/lib/python3.8/site-packages/flask/app.py:1744]
Traceback (most recent call last):
  File "/mnt/c/Users/Administrator/Desktop/html/Chapter-12/venv/lib/python3.8/site-packages/flask/app.py", line 2528, in wsgi_app
    response = self.full_dispatch_request()
  File "/mnt/c/Users/Administrator/Desktop/html/Chapter-12/venv/lib/python3.8/site-packages/flask/app.py", line 1825, in full_dispatch_request
    rv = self.handle_user_exception(e)
  File "/mnt/c/Users/Administrator/Desktop/html/Chapter-12/venv/lib/python3.8/site-packages/flask/app.py", line 1823, in full_dispatch_request
    rv = self.dispatch_request()
  File "/mnt/c/Users/Administrator/Desktop/html/Chapter-12/venv/lib/python3.8/site-packages/flask/app.py", line 1799, in dispatch_request
    return self.ensure_sync(self.view_functions[rule.endpoint])(**view_args)
  File "/mnt/c/Users/Administrator/Desktop/html/Chapter-12/venv/lib/python3.8/site-packages/flask_login/utils.py", line 290, in decorated_view
    return current_app.ensure_sync(func)(*args, **kwargs)
  File "/mnt/c/Users/Administrator/Desktop/html/Chapter-12/app/routes.py", line 50, in profile
    if posts.has_next else None
AttributeError: 'list' object has no attribute 'has_next'
2023-06-01 11:55:30,045 INFO: Tinker Full-stack App [in /mnt/c/Users/Administrator/Desktop/html/Chapter-12/app/__init__.py:48]
2023-06-01 11:55:31,930 ERROR: Exception on /sd/profile [GET] [in /mnt/c/Users/Administrator/Desktop/html/Chapter-12/venv/lib/python3.8/site-packages/flask/app.py:1744]
Traceback (most recent call last):
  File "/mnt/c/Users/Administrator/Desktop/html/Chapter-12/venv/lib/python3.8/site-packages/flask/app.py", line 2528, in wsgi_app
    response = self.full_dispatch_request()
  File "/mnt/c/Users/Administrator/Desktop/html/Chapter-12/venv/lib/python3.8/site-packages/flask/app.py", line 1825, in full_dispatch_request
    rv = self.handle_user_exception(e)
  File "/mnt/c/Users/Administrator/Desktop/html/Chapter-12/venv/lib/python3.8/site-packages/flask/app.py", line 1823, in full_dispatch_request
    rv = self.dispatch_request()
  File "/mnt/c/Users/Administrator/Desktop/html/Chapter-12/venv/lib/python3.8/site-packages/flask/app.py", line 1799, in dispatch_request
    return self.ensure_sync(self.view_functions[rule.endpoint])(**view_args)
  File "/mnt/c/Users/Administrator/Desktop/html/Chapter-12/venv/lib/python3.8/site-packages/flask_login/utils.py", line 290, in decorated_view
    return current_app.ensure_sync(func)(*args, **kwargs)
  File "/mnt/c/Users/Administrator/Desktop/html/Chapter-12/app/routes.py", line 50, in profile
    if posts.has_next else None
AttributeError: 'list' object has no attribute 'has_next'
2023-06-01 11:55:48,762 INFO: Tinker Full-stack App [in /mnt/c/Users/Administrator/Desktop/html/Chapter-12/app/__init__.py:48]
2023-06-01 11:55:50,329 ERROR: Exception on /sd/profile [GET] [in /mnt/c/Users/Administrator/Desktop/html/Chapter-12/venv/lib/python3.8/site-packages/flask/app.py:1744]
Traceback (most recent call last):
  File "/mnt/c/Users/Administrator/Desktop/html/Chapter-12/venv/lib/python3.8/site-packages/flask/app.py", line 2528, in wsgi_app
    response = self.full_dispatch_request()
  File "/mnt/c/Users/Administrator/Desktop/html/Chapter-12/venv/lib/python3.8/site-packages/flask/app.py", line 1825, in full_dispatch_request
    rv = self.handle_user_exception(e)
  File "/mnt/c/Users/Administrator/Desktop/html/Chapter-12/venv/lib/python3.8/site-packages/flask/app.py", line 1823, in full_dispatch_request
    rv = self.dispatch_request()
  File "/mnt/c/Users/Administrator/Desktop/html/Chapter-12/venv/lib/python3.8/site-packages/flask/app.py", line 1799, in dispatch_request
    return self.ensure_sync(self.view_functions[rule.endpoint])(**view_args)
  File "/mnt/c/Users/Administrator/Desktop/html/Chapter-12/venv/lib/python3.8/site-packages/flask_login/utils.py", line 290, in decorated_view
    return current_app.ensure_sync(func)(*args, **kwargs)
  File "/mnt/c/Users/Administrator/Desktop/html/Chapter-12/app/routes.py", line 50, in profile
    if posts.has_next else None
AttributeError: 'list' object has no attribute 'has_next'
2023-06-01 12:01:24,157 ERROR: Exception on /sd/profile [GET] [in /mnt/c/Users/Administrator/Desktop/html/Chapter-12/venv/lib/python3.8/site-packages/flask/app.py:1744]
Traceback (most recent call last):
  File "/mnt/c/Users/Administrator/Desktop/html/Chapter-12/venv/lib/python3.8/site-packages/flask/app.py", line 2528, in wsgi_app
    response = self.full_dispatch_request()
  File "/mnt/c/Users/Administrator/Desktop/html/Chapter-12/venv/lib/python3.8/site-packages/flask/app.py", line 1825, in full_dispatch_request
    rv = self.handle_user_exception(e)
  File "/mnt/c/Users/Administrator/Desktop/html/Chapter-12/venv/lib/python3.8/site-packages/flask/app.py", line 1823, in full_dispatch_request
    rv = self.dispatch_request()
  File "/mnt/c/Users/Administrator/Desktop/html/Chapter-12/venv/lib/python3.8/site-packages/flask/app.py", line 1799, in dispatch_request
    return self.ensure_sync(self.view_functions[rule.endpoint])(**view_args)
  File "/mnt/c/Users/Administrator/Desktop/html/Chapter-12/venv/lib/python3.8/site-packages/flask_login/utils.py", line 290, in decorated_view
    return current_app.ensure_sync(func)(*args, **kwargs)
  File "/mnt/c/Users/Administrator/Desktop/html/Chapter-12/app/routes.py", line 50, in profile
    if posts.has_next else None
AttributeError: 'list' object has no attribute 'has_next'
2023-06-01 12:01:30,160 INFO: Tinker Full-stack App [in /mnt/c/Users/Administrator/Desktop/html/Chapter-12/app/__init__.py:48]
2023-06-01 12:01:31,758 ERROR: Exception on /sd/profile [GET] [in /mnt/c/Users/Administrator/Desktop/html/Chapter-12/venv/lib/python3.8/site-packages/flask/app.py:1744]
Traceback (most recent call last):
  File "/mnt/c/Users/Administrator/Desktop/html/Chapter-12/venv/lib/python3.8/site-packages/flask/app.py", line 2528, in wsgi_app
    response = self.full_dispatch_request()
  File "/mnt/c/Users/Administrator/Desktop/html/Chapter-12/venv/lib/python3.8/site-packages/flask/app.py", line 1825, in full_dispatch_request
    rv = self.handle_user_exception(e)
  File "/mnt/c/Users/Administrator/Desktop/html/Chapter-12/venv/lib/python3.8/site-packages/flask/app.py", line 1823, in full_dispatch_request
    rv = self.dispatch_request()
  File "/mnt/c/Users/Administrator/Desktop/html/Chapter-12/venv/lib/python3.8/site-packages/flask/app.py", line 1799, in dispatch_request
    return self.ensure_sync(self.view_functions[rule.endpoint])(**view_args)
  File "/mnt/c/Users/Administrator/Desktop/html/Chapter-12/venv/lib/python3.8/site-packages/flask_login/utils.py", line 290, in decorated_view
    return current_app.ensure_sync(func)(*args, **kwargs)
  File "/mnt/c/Users/Administrator/Desktop/html/Chapter-12/app/routes.py", line 50, in profile
    if posts.has_next else None
AttributeError: 'list' object has no attribute 'has_next'
2023-06-01 14:36:26,201 INFO: Tinker Full-stack App [in /mnt/c/Users/Administrator/Desktop/html/Chapter-12/app/__init__.py:48]
2023-06-01 14:36:37,727 ERROR: Exception on /sd/profile [GET] [in /mnt/c/Users/Administrator/Desktop/html/Chapter-12/venv/lib/python3.8/site-packages/flask/app.py:1744]
Traceback (most recent call last):
  File "/mnt/c/Users/Administrator/Desktop/html/Chapter-12/venv/lib/python3.8/site-packages/flask/app.py", line 2528, in wsgi_app
    response = self.full_dispatch_request()
  File "/mnt/c/Users/Administrator/Desktop/html/Chapter-12/venv/lib/python3.8/site-packages/flask/app.py", line 1825, in full_dispatch_request
    rv = self.handle_user_exception(e)
  File "/mnt/c/Users/Administrator/Desktop/html/Chapter-12/venv/lib/python3.8/site-packages/flask/app.py", line 1823, in full_dispatch_request
    rv = self.dispatch_request()
  File "/mnt/c/Users/Administrator/Desktop/html/Chapter-12/venv/lib/python3.8/site-packages/flask/app.py", line 1799, in dispatch_request
    return self.ensure_sync(self.view_functions[rule.endpoint])(**view_args)
  File "/mnt/c/Users/Administrator/Desktop/html/Chapter-12/venv/lib/python3.8/site-packages/flask_login/utils.py", line 290, in decorated_view
    return current_app.ensure_sync(func)(*args, **kwargs)
  File "/mnt/c/Users/Administrator/Desktop/html/Chapter-12/app/routes.py", line 50, in profile
    if posts.has_next else None
AttributeError: 'list' object has no attribute 'has_next'
2023-06-01 14:44:00,809 INFO: Tinker Full-stack App [in /mnt/c/Users/Administrator/Desktop/html/Chapter-12/app/__init__.py:48]
2023-06-01 14:45:16,064 INFO: Tinker Full-stack App [in /mnt/c/Users/Administrator/Desktop/html/Chapter-12/app/__init__.py:48]
2023-06-01 14:46:01,134 INFO: Tinker Full-stack App [in /mnt/c/Users/Administrator/Desktop/html/Chapter-12/app/__init__.py:48]
2023-06-01 14:46:28,009 INFO: Tinker Full-stack App [in /mnt/c/Users/Administrator/Desktop/html/Chapter-12/app/__init__.py:48]
2023-06-01 14:47:14,210 INFO: Tinker Full-stack App [in /mnt/c/Users/Administrator/Desktop/html/Chapter-12/app/__init__.py:48]
2023-06-01 14:47:37,861 INFO: Tinker Full-stack App [in /mnt/c/Users/Administrator/Desktop/html/Chapter-12/app/__init__.py:48]
